Workbook
Name Afectación_Económica: '3 PROBABIL E IMPACTO INHERENTE'!$X$9:$X$14
Name AFECTACIÓN_ECONÓMICA_EXTENDIDA: '3 PROBABIL E IMPACTO INHERENTE'!$X$9:$X$14
Name Definicion_tratamiento: '11 FORMULAS'!#REF!
Name E_Relaciones_Laborales: '11 FORMULAS'!$C$12:$C$17
Name Ejecución_administración_de_procesos: Tabla2[Ejecución_administración_de_procesos]
Name Evento_externo: '11 FORMULAS'!$F$45:$F$48
Name F_Usuarios_Productos_y_Prácticas_Organizacionales: '11 FORMULAS'!$C$18:$C$23
Name Fiscal: '11 FORMULAS'!$B$32:$B$43
Name Fiscal_A: '11 FORMULAS'!#REF!
Name Fiscal_B: '11 FORMULAS'!#REF!
Name G_Daños_Activos_Físicos: '11 FORMULAS'!$C$24:$C$26
Name Gestión: '11 FORMULAS'!$A$32:$A$34
Name Gestiòn: '11 FORMULAS'!#REF!
Name Gestión_A: '11 FORMULAS'!#REF!
Name Gestión_B: '11 FORMULAS'!#REF!
Name IMPACTO_PROCESOS: '[1]LISTAS FORMULAS'!$C$3:$C$7
Name IMPACTO_PROCESOS: '[1]LISTAS FORMULAS'!$C$3:$C$7
Name IMPACTO_PROCESOS: '[1]LISTAS FORMULAS'!$C$3:$C$7
Name IMPACTO_PROCESOS: '[1]LISTAS FORMULAS'!$C$3:$C$7
Name IMPACTO_PROCESOS: '[1]LISTAS FORMULAS'!$C$3:$C$7
Name IMPACTO_PROCESOS: '[1]LISTAS FORMULAS'!$C$3:$C$7
Name Infraestructura: '11 FORMULAS'!$E$45:$E$48
Name Integridad_Pública_Corrupción: '11 FORMULAS'!$D$32:$D$43
Name Integridad_Pública_LA_FT_FP: '11 FORMULAS'!$E$32:$E$43
Name IntegridadPública_Corrupción: '11 FORMULAS'!#REF!
Name IntegridadPública_LA_FT_FP: '11 FORMULAS'!#REF!
Name IP_CANALES_LA_FT_FP: 'H1'!$D$30:$D$34
Name IP_CONTRAPARTES_LA_FT_FP: 'H1'!$D$20:$D$24
Name IP_JURISDICCION_LA_FT_FP: 'H1'!$D$35:$D$39
Name IP_PRODUCTOS__LA_FT_FP: 'H1'!$D$25:$D$29
Name NO_APLICA: 'H1'!$U$2
Name opciones: '[1]LISTAS FORMULAS'!$F$3:$F$4
Name opciones: '[1]LISTAS FORMULAS'!$F$3:$F$4
Name opciones: '[1]LISTAS FORMULAS'!$F$3:$F$4
Name opciones: '[1]LISTAS FORMULAS'!$F$3:$F$4
Name opciones: '[1]LISTAS FORMULAS'!$F$3:$F$4
Name opciones: '[1]LISTAS FORMULAS'!$F$3:$F$4
Name opciones2: '[1]LISTAS FORMULAS'!$G$3:$G$5
Name opciones2: '[1]LISTAS FORMULAS'!$G$3:$G$5
Name opciones2: '[1]LISTAS FORMULAS'!$G$3:$G$5
Name opciones2: '[1]LISTAS FORMULAS'!$G$3:$G$5
Name opciones2: '[1]LISTAS FORMULAS'!$G$3:$G$5
Name opciones2: '[1]LISTAS FORMULAS'!$G$3:$G$5
Name Plan_accion: '11 FORMULAS'!#REF!
Name Plan_acción: '11 FORMULAS'!#REF!
Name Plan_de_acción: '11 FORMULAS'!#REF!
Name Posibilidad__de_efecto_dañoso_sobre_el_interes_patrimonial: '11 FORMULAS'!#REF!
Name Posibilidad_de_pérdida_Económica: '11 FORMULAS'!#REF!
Name Quince_Cero: '[1]LISTAS FORMULAS'!$F$14:$F$15
Name Quince_Cero: '[1]LISTAS FORMULAS'!$F$14:$F$15
Name Quince_Cero: '[1]LISTAS FORMULAS'!$F$14:$F$15
Name Quince_Cero: '[1]LISTAS FORMULAS'!$F$14:$F$15
Name Quince_Cero: '[1]LISTAS FORMULAS'!$F$14:$F$15
Name Quince_Cero: '[1]LISTAS FORMULAS'!$F$14:$F$15
Name Rango_Calificacion_Ejecucion: '[1]LISTAS FORMULAS'!$H$3:$H$5
Name Rango_Calificacion_Ejecucion: '[1]LISTAS FORMULAS'!$H$3:$H$5
Name Rango_Calificacion_Ejecucion: '[1]LISTAS FORMULAS'!$H$3:$H$5
Name Rango_Calificacion_Ejecucion: '[1]LISTAS FORMULAS'!$H$3:$H$5
Name Rango_Calificacion_Ejecucion: '[1]LISTAS FORMULAS'!$H$3:$H$5
Name Rango_Calificacion_Ejecucion: '[1]LISTAS FORMULAS'!$H$3:$H$5

Sheet INSTRUCTIVO ACTIVOS
A1: INSTRUCTIVO DILIGENCIAMIENTO DE ACTIVOS DE INFORMACIÓN
A2: OBJETIVO Establecer de manera clara, detallada y paso a paso la forma correcta de diligenciar cada campo del Formato de Gestión y Clasificación de Activos de Información, permitiendo a las dependencias de la entidad identificar, clasificar, valorar y proteger sus activos de información conforme a los lineamientos del Modelo de Seguridad y Privacidad de la Información (MSPI), ISO 27001, Ley 1712 de 2014, Ley 1581 de 2012 y demás normatividad aplicable. A continuación se presenta el diligenciamiento fila por fila para facilitar el registro del formato.
A3: FASE | B3: Columna | C3: Descripción - Lineamientos para el diligenciamiento
A4: FASE 1 | B4: MACROPROCESO | C4: Seleccione el macroproceso de la lista desplegable entre: Direccionamiento Estratégico Gestión de la Información y las Comunicaciones Gestión de Servicios de Salud Gestión Educativa Convivencia Ciudadana, Seguridad y Orden Público Desarrollo Social Integral y Ambiental del Territorio Gestión Financiera Gestión Catastral Gestión Administrativa Gestión del Talento Humano Gestión Jurídica Gestión Estadística Control Interno
B5: PROCESO | C5: Seleccione el proceso relacionado con el macroproceso y con el activo de información de la lista desplegable.
B6: CÓDIGO DEL SISTEMA DE GESTIÓN DOCUMENTAL | C6: Diligencie el código documental asignado en la Tabla de Retención Documental (TDR) o instrumentos archivísticos. Si no existe, escriba “No aplica”.
B7: IDENTIFICADOR | C7: Registre un código único que permita identificar el activo. Se recomienda usar una combinación de la dependencia + número consecutivo. Por ejemplo, TIC-001
B8: TIPO | C8: Seleccione el tipo de activo de información de la lista desplegable entre: Información (Bases de datos de clientes, contratos, hojas de cálculo financieras, manuales internos, correos electrónicos, reportes de ventas) Software (Sistema ERP, antivirus, sistema operativo Windows/Linux, aplicación contable, CRM, aplicaciones móviles) Hardware (Servidores, computadores portátiles, impresoras, discos duros externos, routers, cámaras de seguridad) Servicios (Servicio de correo electrónico corporativo, hosting web, nube (AWS/Azure), internet empresarial, mesa de ayuda TI) Intangibles (Marca de la empresa, propiedad intelectual, licencias, patentes, reputación corporativa, know-how) Componentes de red (Switches, firewalls, access points Wi-Fi, cables de red, módems, balanceadores de carga) Recurso humano No aplica
B9: OFICINA | C9: Seleccione la dependencia u oficina responsable o relacionada con el activo de información de la lista desplegable entre: Despacho del Alcalde Agricultura Ambiente Asuntos Étnicos Cultura Desarrollo Social Educación Gobierno Gestión Institucional Hacienda Infraestructura Planeación Salud Turismo Vivienda General Jurídica Seguridad y Convivencia Comunicaciones Control I​nterno Control Interno y Disciplinario​ Cooperación Internacion​al​ Tecnologías de la Información y las Comunicaciones​ Progr​amas Especiales​ Posconflicto​ Equidad de Género​ Juventudes Libertad Religiosa Gestión Catastral
B10: SERIE DOCUMENTAL | C10: Ingrese la serie documental del área, dependencia o proceso donde se encuentra identificado el activo. Por ejemplo: Si el activo se encuentra en la secretaría jurírica y el activo es un PROCESO JURIDICO el número de serie 34-42
B11: SUBSERIE DOCUMENTAL | C11: Ingrese la subserie documental correspondiente a la serie donde se encuentra el activo. Por ejemplo: Para el PROCESO JURIDICO si es un proceso de cobro coactivo el número de serie sería 34-42 01
B12: NOMBRE | C12: Registre el nombre del activo de información de forma clara y específica.
B13: DESCRIPCIÓN | C13: Describa de manera resumida la función, contenido o propósito del activo.
B14: NOMBRE DEL RESPONSABLE DE LA PRODUCCIÓN DE LA INFORMACIÓN (PROPIETARIO DEL ACTIVO) | C14: Diligencie el nombre completo de la persona encargada de crear, generar o administrar funcionalmente la información.
B15: FECHA DE GENERACIÓN DE LA INFORMACIÓN | C15: Ingrese la fecha en la que el activo de información fue creado o comenzó a generarse.
B16: NOMBRE DEL RESPONSABLE DE LA INFORMACIÓN (CUSTODIO DEL ACTIVO) | C16: Ingrese el nombre completo de la persona encargada de custodiar, almacenar o mantener el activo.
... B20: IDIOMA | C20: Establezca el idioma en el que está redactado o disponible el activo.
A22: FASE 2 | B22: CONFIDENCIALIDAD | C22: Seleccione el nivel de restricción del activo de información según el acceso permitido de la lista desplegable entre: Información pública reservada: Es la información que no debe ser divulgada debido a que esto puede causar daño a intereses públicos. Solamente la Constitución o la ley pueden definir qué información es de carácter reservado. Información pública clasificada: Es la información que no debe ser divulgada debido a que se pueden vulnerar los derechos de las personas naturales o jurídicas, tales como: derecho de las personas a la intimidad, derecho a la vida, salud o seguridad y los secretos comerciales, industriales y profesionales. Información pública: Información que puede ser entregada o publicada sin restricciones a cualquier persona dentro y fuera de la entidad, sin que esto implique daños a terceros ni a las actividades y procesos de la entidad. No clasificada: Activos de Información que deben ser incluidos en el inventario y que aún no han sido clasificados, deben ser tratados como activos de INFORMACIÓN PÚBLICA RESERVADA. como: Hardware, Colaboradores de Planta o Contratistas
B23: INTEGRIDAD | C23: Seleccione el nivel de importancia relacionado con la exactitud y completitud de la información de la lista desplegable entre: Alta: Información cuya pérdida de exactitud y completitud puede conllevar un impacto negativo de índole legal o económica, retrasar sus funciones, o generar pérdidas de imagen severas de la entidad. Media: Información cuya pérdida de exactitud y completitud puede conllevar un impacto negativo de índole legal o económica, retrasar sus funciones, o generar pérdida de imagen moderada a funcionarios de la entidad. Baja: Información cuya pérdida de exactitud y completitud conlleva un impacto no significativo para la entidad o entes externos. No clasificada: Activos de Información que deben ser incluidos en el inventario y que aún no han sido clasificados, deben ser tratados como activos de información de integridad ALTA.
B24: DISPONIBILIDAD | C24: Seleccione el nivel de necesidad de acceso continuo al activo de información de la lista desplegable entre: Alta: La no disponibilidad de la información puede conllevar un impacto negativo de índole legal o económica, retrasar sus funciones, o generar pérdidas de imagen severas a entes externos. Media: La no disponibilidad de la información puede conllevar un impacto negativo de índole legal o económica, retrasar sus funciones, o generar pérdida de imagen moderada de la entidad. Baja: La no disponibilidad de la información puede afectar la operación normal de la entidad o entes externos, pero no conlleva implicaciones legales, económicas o de pérdida de imagen. No clasificada: Activos de Información que deben ser incluidos en el inventario y que aún no han sido clasificados, deben ser tratados como activos de información de disponibilidad ALTA.
B25: INFORMACIÓN PUBLICADA | C25: Seleccione el estado de publicación de la información de la lista desplegable entre: Publicada Disponible a solicitud No publicada o disponible
B26: LUGAR DE CONSULTA O UBICACIÓN | C26: Seleccione el lugar físico o digital donde se consulta o almacena el activo de la lista desplegable entre: Portal web propios Portal web de terceros Intranet Archivo físico Archivo digital Sistema de información Base de datos
A28: FASE 3 | B28: OBJETO LEGÍTIMO DE LA EXCEPCIÓN | C28: Se refiere a la justificación jurídica válida que permite reservar, clasificar o denegar el acceso a cierta información pública. Es la causal o motivo legal, como la protección de datos personales o la seguridad nacional, que autoriza a las entidades estatales a mantener documentos en reserva. (por ejemplo, por razones de seguridad, confidencialidad, o acceso restringido).
B29: FUNDAMENTO CONSTITUCIONAL O LEGAL | C29: Registrar la norma o artículo que soporta la clasificación o reserva de la información. Ejemplo: “Ley 1581 de 2012” para tipos de activo software, “Ley 1712 de 2014” para todos los demás activos“ Constitución Política Art. 15”.
B30: EXCEPCIÓN TOTAL O PARCIAL | C30: Indicar si la restricción aplica sobre toda la información o solo una parte de ella. Seleccione de la lista desplegable entre: Total Parical Sin excepción
B31: FECHA DE CLASIFICACIÓN | C31: Registrar la fecha en la cual el activo fue clasificado como reservado o clasificado. Utilizar formato DD/MM/AAAA. Ejemplo: “15/01/2026”.
B32: TIEMPO DE LA CLASIFICACIÓN | C32: Registrar el tiempo durante el cual la información permanecerá clasificada o reservada, según la normatividad aplicable. Ejemplo: “15 años”, “5 años”, “Permanente”.
A34: FASE 4 | B34: ¿CONTIENE DATOS PERSONALES? | C34: Seleccione si el activo contiene información asociada a personas naturales identificadas o identificables de la lista desplegable entre: Sí No. Por ejempolo si es de “Nómina = Sí”.
B35: ¿CONTIENE DATOS DE NIÑOS, NIÑAS O ADOLESCENTES? | C35: "Seleccione si el activo contiene información asociada a personas naturales identificadas o identificables de la lista desplegable entre: Sí No. Por ejempolo si es de “Base de datos estudiantil= Sí”."
B36: TIPOS DE DATOS PERSONALES | C36: Seleccione el tipo de dato personal contenido en el activo de la lista desplegable entre: Dato público: Información que puede ser conocida y consultada por cualquier persona sin necesidad de autorización del titular, debido a que no afecta su intimidad ni genera riesgos de discriminación. Ejemplo: nombre, estado civil, profesión u oficio, calidad de comerciante o servidor público. Dato semiprivado: Información que no tiene naturaleza íntima, reservada ni pública, y cuyo conocimiento puede interesar tanto al titular como a un grupo determinado de personas o a la sociedad. Su acceso está sujeto a ciertos controles. Ejemplo: historial crediticio, información financiera o comercial. Dato privado: Información que únicamente interesa al titular por su carácter íntimo o reservado y que no debe ser conocida públicamente sin autorización. Ejemplo: dirección de residencia, número telefónico personal, correos electrónicos personales o información laboral interna. Dato sensible: Información que puede afectar la intimidad del titular o generar discriminación en caso de ser divulgada. Requiere especial protección legal. Ejemplo: origen racial o étnico, orientación política, convicciones religiosas, datos biométricos, información de salud, orientación sexual. Dato vulnerable: Información asociada a personas que requieren protección especial debido a condiciones particulares de edad, discapacidad, situación social o dependencia. Incluye datos de menores de edad, adultos mayores, víctimas del conflicto, personas con discapacidad, entre otros. No aplica: Clasificación utilizada cuando la información evaluada no corresponde a datos personales o no contiene información relacionada con personas naturales identificadas o identificables.
B37: FINALIDAD DE LA RECOLECCIÓN DE LOS DATOS PERSONALES | C37: Registrar el propósito para el cual fueron recolectados los datos personales. Ejemplo: “Gestión de pagos salariales”, “Atención al ciudadano”, “Gestión académica”.
B38: EXISTE AUTORIZACIÓN PARA EL TRATAMIENTO DE DATOS PERSONALES | C38: Indicar si la entidad cuenta con autorización para el tratamiento de los datos personales.
A40: Nota: Si el campo no aplica al activo, escriba “No aplica” únicamente cuando el instructivo o el formato lo permitan.

Sheet ACTIVOS DE INFORMACIÓN
A8: ç | B8: FORMATO DE GESTIÓN Y CLASIFICACIÓN DE ACTIVOS DE INFORMACIÓN | AL8: Código: GIC-TEI-F-09
AL9: Fecha actualización:08/05/2026
AL10: Versión: 1
A12: IDENTIFICACIÓN DEL ACTIVO DE INFORMACIÓN ( LEY 594 DE 2000 - LEY 1712 DE 2014- DECRETO 103 DE 2015 - DECRETO 1080 DE 2015 - ISO 27001 ) | T12: CLASIFICACIÓN DEL ACTIVO DE INFORMACIÓN ( ISO 27001 ) | AC12: ÍNDICE DE INFORMACIÓN CLASIFICADA Y RESERVADA ( DECRETO 103 DE 2015) | AI12: DATOS PERSONALES ( LEY 1581 DE 2012) | AZ12: IDENTIFICACIÓN DEL ACTIVO DE INFORMACIÓN ( LEY 594 DE 2000 - LEY 1712 DE 2014- DECRETO 103 DE 2015 - DECRETO 1080 DE 2015 - ISO 27001 ) | BG12: CLASIFICACIÓN DEL ACTIVO DE INFORMACIÓN ( ISO 27001 ) | BM12: INDICE DE INFORMACIÓN CLASIFICADA O RESERVADA
A13: Proceso | B13: Subproceso | C13: Código del sistema de gestión documental | D13: Identificador | E13: Tipo | F13: Dependencia | G13: Serie documental | H13: Subserie documental | I13: Nombre | J13: Cantidad | K13: Descripción | L13: Cargo de la producción de la información ( Propietario del activo) | M13: Fecha de generación de la información | N13: Cargo de la persona encargada de la información (Custodio del activo) | O13: Fecha de ingreso del activo al archivo | P13: Soporte de registro | Q13: Medio de conservación | R13: Formato | S13: Idioma | T13: Confidencialidad | U13: C | V13: Integridad | W13: I | X13: Disponibilidad | Y13: D | Z13: Criticidad del activo | AA13: Información publicada | AB13: Lugar de consulta o ubicación | AC13: Objeto legítimo de la excepción | AD13: Fundamento constitucional o legal | AE13: Fundamento jurídico de la excepción | AF13: Excepción total o parcial | AG13: Fecha de clasificación (DD/MM/AAAA) | AH13: Tiempo de clasificación | AI13: ¿Contiene datos personales? | AJ13: ¿Contiene datos personales de niños, niñas o adolescentes? | AK13: Tipos de datos personales | AL13: Finalidad de la recolección de los datos personales | AM13: Existe la autorización para el tratamiento de los datos personales | AZ13: Tipo | BA13: Estado | BB13: Soporte de registro | BC13: Oficina | BD13: Medio de Conservación | BE13: Formato | BG13: Confidencialidad | BH13: Integridad | BI13: Disponibilidad | BJ13: Información publicada | BK13: Lugar de consulta o ubicación | BM13: Objeto legítimo de la excepción | BN13: Excepción total o parcial | BO13: Fundamento de constitución legal | BR13: ¿Contiene datos personales? | BS13: ¿Contiene datos personales de niños, niñas o adolescentes? | BT13: Tipos de datos personales | BU13: Finalidad de la recolección de los datos personales | BV13: Existe la autorización para el tratamiento de los datos personales | BX13: Direccionamiento Estratégico | BY13: Gestión de la Información y las Comunicaciones | BZ13: Gestión de Servicios de Salud | CA13: Gestión Educativa | CB13: Convivencia Ciudadana, Seguridad y Orden Público | CC13: Desarrollo Social Integral y Ambiental del Territorio | CD13: Gestión Financiera | CE13: Gestión Catastral | CF13: Gestión Administrativa | CG13: Gestión del Talento Humano | CH13: Gestión Jurídica | CI13: Gestión Estadística | CJ13: Control Interno | CL13: Macroproceso | CM13: Proceso
A14: Desarrollo Social Integral y Ambiental del Territorio | B14: Gestión Turística | E14: Software | F14: Turismo | I14: SISNET | J14: 1 | K14: Software de gestión de correspondencia. | L14: Auxiliar administrativa | M14: 46178 | N14: Profesional Atención al ciudadano. | O14: N/A | P14: Fisico | Q14: Digital | R14: Sistema de Información | T14: Información pública clasificada | U14: =IF(T14="No clasificada",5,IF(T14="Información pública clasificada",3,IF(T14="Información pública reservada",5,IF(T14="Información pública",1,)))) -> 3 | V14: Media | W14: =IF(V14="No clasificada",5,IF(V14="Baja",1,IF(V14="Media",3,IF(V14="Alta",5,)))) -> 3 | X14: Baja | Y14: =IF(X14="No clasificada",5,IF(X14="Baja",1,IF(X14="Media",3,IF(X14="Alta",5,)))) -> 1 | Z14: =IF(OR(T14=0,V14=0,X14=0),"FALTAN DATOS",IF(AND(U14=1,W14=1,Y14=1),"BAJA",(IF(OR(AND(U14=5,W14=5),AND(U14=5,Y14=5),AND(U14=5,Y14=5),AND(U14=5,W14=5,Y14=5)),"ALTA","MEDIA")))) -> MEDIA | AA14: No publicada o disponible | AB14: Portal web de terceros | AC14: Sí | AD14: =IF(AC14="Sí","Ley 1581 de 2012",IF(AC14="No","Ley 1755 de 2015","")) -> Ley 1581 de 2012 | AE14: =IF(AC14="Sí","Artículo 10 y 13",IF(AC14="No","Artículo 27","")) -> Artículo 10 y 13 | AF14: Parcial | AG14: 46167 | AH14: 1 año | AZ14: Información | BA14: Vigente | BB14: Fisico | BC14: Despacho del Alcalde | BD14: Fisico | BE14: Audio | BG14: Información pública reservada | BH14: Alta | BI14: Alta | BJ14: Publicada | BK14: Portal web propios | BM14: Sí | BN14: Total | BO14: Ley 1581 de 2012 | BP14: Artículo 10 y 13 | BR14: Sí | BS14: Sí | BT14: Dato público | BV14: Sí | BX14: Banco de Programas y Proyectos | BY14: Comunicación Pública | BZ14: Aseguramiento en Salud | CA14: Calidad Educativa | CB14: Convivencia y Cultura Ciudadana (Inspección de policía - comisaría de familia, metrología) | CC14: Gestión de Vivienda y Saneamiento Básico | CD14: Tesorería | CE14: Actualización Catastral | CF14: Atención al Ciudadano | CG14: Administración del Talento Humano | CH14: Gestión Contractual | CI14: Gestión del Sisbén | CJ14: Evaluación a la Gestión | CL14: Direccionamiento Estratégico | CM14: Banco de Programas y Proyectos
A15: Desarrollo Social Integral y Ambiental del Territorio | B15: Gestión Turística | E15: Servicios | F15: Turismo | I15: Sistema de Correo Institucional | J15: 1 | K15: Plataforma de correo electrónico institucional para comunicaciones oficiales. | L15: Secretario de despacho | M15: 46178 | N15: Técnico administrativo 1 -Oficina TIC | O15: N/A | Q15: Digital | R15: Otro | T15: Información pública clasificada | U15: =IF(T15="No clasificada",5,IF(T15="Información pública clasificada",3,IF(T15="Información pública reservada",5,IF(T15="Información pública",1,)))) -> 3 | V15: Alta | W15: =IF(V15="No clasificada",5,IF(V15="Baja",1,IF(V15="Media",3,IF(V15="Alta",5,)))) -> 5 | X15: Alta | Y15: =IF(X15="No clasificada",5,IF(X15="Baja",1,IF(X15="Media",3,IF(X15="Alta",5,)))) -> 5 | Z15: =IF(OR(T15=0,V15=0,X15=0),"FALTAN DATOS",IF(AND(U15=1,W15=1,Y15=1),"BAJA",(IF(OR(AND(U15=5,W15=5),AND(U15=5,Y15=5),AND(U15=5,Y15=5),AND(U15=5,W15=5,Y15=5)),"ALTA","MEDIA")))) -> MEDIA | AA15: No publicada o disponible | AB15: Portal web de terceros | AC15: No | AD15: =IF(AC15="Sí","Ley 1581 de 2012",IF(AC15="No","Ley 1755 de 2015","")) -> Ley 1755 de 2015 | AE15: =IF(AC15="Sí","Artículo 10 y 13",IF(AC15="No","Artículo 27","")) -> Artículo 27 | AF15: Parcial | AG15: 46167 | AH15: 1 año | AZ15: Software | BA15: Obsoleto | BB15: Digital | BC15: Agricultura | BD15: Digital | BE15: Documento de texto | BG15: Información pública clasificada | BH15: Media | BI15: Media | BJ15: Disponible a solicitud | BK15: Portal web de terceros | BM15: No | BN15: Parcial | BO15: Ley 1755 de 2015 | BP15: Artículo 27 | BR15: No | BS15: No | BT15: Dato semiprivado | BV15: No | BX15: Gestión para el Mejoramiento Institucional | BY15: Tecnologías de la Información | BZ15: Salud Pública | CA15: Cobertura Educativa | CB15: Gestión de Riesgo de Desastres | CC15: Gestión Cultural | CD15: Fiscalización | CE15: Conservación Catastral | CF15: Gestión Documental (Archivo - Ventanilla Única) | CG15: Seguridad y Salud en el Trabajo | CH15: Defensa Judicial | CI15: Información Estadística | CL15: Gestión de la Información y las Comunicaciones | CM15: Gestión para el Mejoramiento Institucional
A16: Desarrollo Social Integral y Ambiental del Territorio | B16: Gestión Turística | E16: Software | F16: Turismo | I16: Repositorio Archivo digital de correspondecia | J16: 1 | K16: Base de datos en Drive de la correspondencia fisica escaneada y digital | L16: Secretario de despacho | M16: 46178 | N16: Técnico administrativo 1 -Oficina TIC | O16: N/A | Q16: Digital | R16: Sistema de Información | T16: Información pública reservada | U16: =IF(T16="No clasificada",5,IF(T16="Información pública clasificada",3,IF(T16="Información pública reservada",5,IF(T16="Información pública",1,)))) -> 5 | V16: Alta | W16: =IF(V16="No clasificada",5,IF(V16="Baja",1,IF(V16="Media",3,IF(V16="Alta",5,)))) -> 5 | X16: Alta | Y16: =IF(X16="No clasificada",5,IF(X16="Baja",1,IF(X16="Media",3,IF(X16="Alta",5,)))) -> 5 | Z16: =IF(OR(T16=0,V16=0,X16=0),"FALTAN DATOS",IF(AND(U16=1,W16=1,Y16=1),"BAJA",(IF(OR(AND(U16=5,W16=5),AND(U16=5,Y16=5),AND(U16=5,Y16=5),AND(U16=5,W16=5,Y16=5)),"ALTA","MEDIA")))) -> ALTA | AA16: No publicada o disponible | AB16: Portal web de terceros | AC16: Sí | AD16: =IF(AC16="Sí","Ley 1581 de 2012",IF(AC16="No","Ley 1755 de 2015","")) -> Ley 1581 de 2012 | AF16: Total | AG16: 46177 | AH16: 1 año | AZ16: Hardware | BA16: Otro | BB16: Electronico | BC16: Ambiente | BD16: No aplica | BE16: Documento PDF | BG16: Información pública | BH16: Baja | BI16: Baja | BJ16: No publicada o disponible | BK16: Intranet | BM16: No aplica | BN16: Sin excepción | BT16: Dato privado | BX16: Ordenamiento Territorial | BZ16: Salud Ambiental | CA16: Inspección y Vigilancia Educativa | CB16: Víctimas | CC16: Gestión Turística | CD16: Contabilidad General | CF16: Administración Plaza de Mercado | CG16: Control Disciplinario | CH16: Juzgamiento Disciplinario | CL16: Gestión de Servicios de Salud | CM16: Ordenamiento Territorial
A17: Desarrollo Social Integral y Ambiental del Territorio | B17: Gestión Turística | E17: Servicios | F17: Turismo | I17: GECO | J17: 1 | K17: Plataforma de gestión contractual | L17: Secretario de despacho | M17: 46178 | N17: Secretaría Jurídica | O17: N/A | P17: Digital | Q17: Sistema de Información | R17: Sistema de Información | T17: Información pública reservada | U17: =IF(T17="No clasificada",5,IF(T17="Información pública clasificada",3,IF(T17="Información pública reservada",5,IF(T17="Información pública",1,)))) -> 5 | V17: Alta | W17: =IF(V17="No clasificada",5,IF(V17="Baja",1,IF(V17="Media",3,IF(V17="Alta",5,)))) -> 5 | X17: Baja | Y17: =IF(X17="No clasificada",5,IF(X17="Baja",1,IF(X17="Media",3,IF(X17="Alta",5,)))) -> 1 | Z17: =IF(OR(T17=0,V17=0,X17=0),"FALTAN DATOS",IF(AND(U17=1,W17=1,Y17=1),"BAJA",(IF(OR(AND(U17=5,W17=5),AND(U17=5,Y17=5),AND(U17=5,Y17=5),AND(U17=5,W17=5,Y17=5)),"ALTA","MEDIA")))) -> ALTA | AA17: No publicada o disponible | AB17: Base de datos | AC17: No aplica | AD17: =IF(AC17="Sí","Ley 1581 de 2012",IF(AC17="No","Ley 1755 de 2015","")) | AE17: =IF(AC17="Sí","Artículo 10 y 13",IF(AC17="No","Artículo 27","")) | AF17: Sin excepción | AG17: 46177 | AH17: 1 año | AZ17: Servicios | BA17: No aplica | BB17: No aplica | BC17: Asuntos Étnicos | BE17: Presentación | BG17: No clasificada | BH17: No clasificada | BI17: No clasificada | BK17: Archivo físico | BT17: Dato sensible | BX17: Cooperación Internacional | BZ17: Defensa de los Derechos de los Ciudadanos | CB17: Gestión de Movilidad y Seguridad Vial | CC17: Gestión para las Comunidades Étnicas | CD17: Gestión Presupuestal | CF17: Gestión de Inventarios de Bienes Muebles e Inmuebles | CL17: Gestión Educativa | CM17: Cooperación Internacional
A18: Desarrollo Social Integral y Ambiental del Territorio | B18: Gestión Turística | E18: Hardware | F18: Turismo | I18: Portal web | J18: 1 | K18: Vivejamundi.com, es la plataforma digital oficial que promociona la oferta turística del Municipio. (Directorio oficial de operadores turísticos de Jamundí) | L18: Secretario de Despacho | M18: 46178 | N18: Jefe de Oficina Comunicaciones | O18: N/A | P18: Digital | Q18: Digital | R18: Otro | T18: Información pública | U18: =IF(T18="No clasificada",5,IF(T18="Información pública clasificada",3,IF(T18="Información pública reservada",5,IF(T18="Información pública",1,)))) -> 1 | V18: Media | W18: =IF(V18="No clasificada",5,IF(V18="Baja",1,IF(V18="Media",3,IF(V18="Alta",5,)))) -> 3 | X18: Alta | Y18: =IF(X18="No clasificada",5,IF(X18="Baja",1,IF(X18="Media",3,IF(X18="Alta",5,)))) -> 5 | Z18: =IF(OR(T18=0,V18=0,X18=0),"FALTAN DATOS",IF(AND(U18=1,W18=1,Y18=1),"BAJA",(IF(OR(AND(U18=5,W18=5),AND(U18=5,Y18=5),AND(U18=5,Y18=5),AND(U18=5,W18=5,Y18=5)),"ALTA","MEDIA")))) -> MEDIA | AA18: Publicada | AB18: Portal web propios | AC18: No aplica | AD18: =IF(AC18="Sí","Ley 1581 de 2012",IF(AC18="No","Ley 1755 de 2015","")) | AE18: =IF(AC18="Sí","Artículo 10 y 13",IF(AC18="No","Artículo 27","")) | AF18: Sin excepción | AG18: 46177 | AH18: 1 año | AZ18: Intangibles | BC18: Cultura | BE18: Hoja de calculo | BK18: Archivo digital | BT18: Dato vulnerable | BX18: Gestión Presupuestal | CC18: Mantenimiento Espacios de Uso Público e Infraestructura Vial | CL18: Convivencia Ciudadana, Seguridad y Orden Público | CM18: Gestión Presupuestal
U19: =IF(T19="No clasificada",5,IF(T19="Información pública clasificada",3,IF(T19="Información pública reservada",5,IF(T19="Información pública",1,)))) -> 0 | W19: =IF(V19="No clasificada",5,IF(V19="Baja",1,IF(V19="Media",3,IF(V19="Alta",5,)))) -> 0 | Y19: =IF(X19="No clasificada",5,IF(X19="Baja",1,IF(X19="Media",3,IF(X19="Alta",5,)))) -> 0 | Z19: =IF(OR(T19=0,V19=0,X19=0),"FALTAN DATOS",IF(AND(U19=1,W19=1,Y19=1),"BAJA",(IF(OR(AND(U19=5,W19=5),AND(U19=5,Y19=5),AND(U19=5,Y19=5),AND(U19=5,W19=5,Y19=5)),"ALTA","MEDIA")))) -> FALTAN DATOS | AD19: =IF(AC19="Sí","Ley 1581 de 2012",IF(AC19="No","Ley 1755 de 2015","")) | AE19: =IF(AC19="Sí","Artículo 10 y 13",IF(AC19="No","Artículo 27","")) | AZ19: Componentes de red | BC19: Desarrollo Social | BE19: Imagen | BK19: Sistema de información | BT19: No aplica | CC19: Sostenibilidad Ambiental y Minera | CL19: Desarrollo Social Integral y Ambiental del Territorio | CM19: Comunicación Pública
U20: =IF(T20="No clasificada",5,IF(T20="Información pública clasificada",3,IF(T20="Información pública reservada",5,IF(T20="Información pública",1,)))) -> 0 | W20: =IF(V20="No clasificada",5,IF(V20="Baja",1,IF(V20="Media",3,IF(V20="Alta",5,)))) -> 0 | Y20: =IF(X20="No clasificada",5,IF(X20="Baja",1,IF(X20="Media",3,IF(X20="Alta",5,)))) -> 0 | Z20: =IF(OR(T20=0,V20=0,X20=0),"FALTAN DATOS",IF(AND(U20=1,W20=1,Y20=1),"BAJA",(IF(OR(AND(U20=5,W20=5),AND(U20=5,Y20=5),AND(U20=5,Y20=5),AND(U20=5,W20=5,Y20=5)),"ALTA","MEDIA")))) -> FALTAN DATOS | AD20: =IF(AC20="Sí","Ley 1581 de 2012",IF(AC20="No","Ley 1755 de 2015","")) | AE20: =IF(AC20="Sí","Artículo 10 y 13",IF(AC20="No","Artículo 27","")) | AZ20: Recurso humano | BC20: Educación | BE20: Video | BK20: Base de datos | CC20: Atención Social y Participación Ciudadana | CL20: Gestión Financiera | CM20: Tecnologías de la Información
U21: =IF(T21="No clasificada",5,IF(T21="Información pública clasificada",3,IF(T21="Información pública reservada",5,IF(T21="Información pública",1,)))) -> 0 | W21: =IF(V21="No clasificada",5,IF(V21="Baja",1,IF(V21="Media",3,IF(V21="Alta",5,)))) -> 0 | Y21: =IF(X21="No clasificada",5,IF(X21="Baja",1,IF(X21="Media",3,IF(X21="Alta",5,)))) -> 0 | Z21: =IF(OR(T21=0,V21=0,X21=0),"FALTAN DATOS",IF(AND(U21=1,W21=1,Y21=1),"BAJA",(IF(OR(AND(U21=5,W21=5),AND(U21=5,Y21=5),AND(U21=5,Y21=5),AND(U21=5,W21=5,Y21=5)),"ALTA","MEDIA")))) -> FALTAN DATOS | AD21: =IF(AC21="Sí","Ley 1581 de 2012",IF(AC21="No","Ley 1755 de 2015","")) | AE21: =IF(AC21="Sí","Artículo 10 y 13",IF(AC21="No","Artículo 27","")) | AZ21: No aplica | BC21: Gobierno | BE21: Base de datos | CC21: Desarrollo Agropecuario | CL21: Gestión Catastral | CM21: Aseguramiento en Salud
U22: =IF(T22="No clasificada",5,IF(T22="Información pública clasificada",3,IF(T22="Información pública reservada",5,IF(T22="Información pública",1,)))) -> 0 | W22: =IF(V22="No clasificada",5,IF(V22="Baja",1,IF(V22="Media",3,IF(V22="Alta",5,)))) -> 0 | Y22: =IF(X22="No clasificada",5,IF(X22="Baja",1,IF(X22="Media",3,IF(X22="Alta",5,)))) -> 0 | Z22: =IF(OR(T22=0,V22=0,X22=0),"FALTAN DATOS",IF(AND(U22=1,W22=1,Y22=1),"BAJA",(IF(OR(AND(U22=5,W22=5),AND(U22=5,Y22=5),AND(U22=5,Y22=5),AND(U22=5,W22=5,Y22=5)),"ALTA","MEDIA")))) -> FALTAN DATOS | AD22: =IF(AC22="Sí","Ley 1581 de 2012",IF(AC22="No","Ley 1755 de 2015","")) | AE22: =IF(AC22="Sí","Artículo 10 y 13",IF(AC22="No","Artículo 27","")) | BC22: Gestión Institucional | BE22: Otro | CC22: Gestión para el Posconflicto | CL22: Gestión Administrativa | CM22: Salud Pública
U23: =IF(T23="No clasificada",5,IF(T23="Información pública clasificada",3,IF(T23="Información pública reservada",5,IF(T23="Información pública",1,)))) -> 0 | W23: =IF(V23="No clasificada",5,IF(V23="Baja",1,IF(V23="Media",3,IF(V23="Alta",5,)))) -> 0 | Y23: =IF(X23="No clasificada",5,IF(X23="Baja",1,IF(X23="Media",3,IF(X23="Alta",5,)))) -> 0 | Z23: =IF(OR(T23=0,V23=0,X23=0),"FALTAN DATOS",IF(AND(U23=1,W23=1,Y23=1),"BAJA",(IF(OR(AND(U23=5,W23=5),AND(U23=5,Y23=5),AND(U23=5,Y23=5),AND(U23=5,W23=5,Y23=5)),"ALTA","MEDIA")))) -> FALTAN DATOS | AD23: =IF(AC23="Sí","Ley 1581 de 2012",IF(AC23="No","Ley 1755 de 2015","")) | AE23: =IF(AC23="Sí","Artículo 10 y 13",IF(AC23="No","Artículo 27","")) | BC23: Hacienda | BE23: No aplica | CL23: Gestión del Talento Humano | CM23: Salud Ambiental
U24: =IF(T24="No clasificada",5,IF(T24="Información pública clasificada",3,IF(T24="Información pública reservada",5,IF(T24="Información pública",1,)))) -> 0 | W24: =IF(V24="No clasificada",5,IF(V24="Baja",1,IF(V24="Media",3,IF(V24="Alta",5,)))) -> 0 | Y24: =IF(X24="No clasificada",5,IF(X24="Baja",1,IF(X24="Media",3,IF(X24="Alta",5,)))) -> 0 | Z24: =IF(OR(T24=0,V24=0,X24=0),"FALTAN DATOS",IF(AND(U24=1,W24=1,Y24=1),"BAJA",(IF(OR(AND(U24=5,W24=5),AND(U24=5,Y24=5),AND(U24=5,Y24=5),AND(U24=5,W24=5,Y24=5)),"ALTA","MEDIA")))) -> FALTAN DATOS | AD24: =IF(AC24="Sí","Ley 1581 de 2012",IF(AC24="No","Ley 1755 de 2015","")) | AE24: =IF(AC24="Sí","Artículo 10 y 13",IF(AC24="No","Artículo 27","")) | BC24: Infraestructura | CL24: Gestión Jurídica | CM24: Defensa de los Derechos de los Ciudadanos
U25: =IF(T25="No clasificada",5,IF(T25="Información pública clasificada",3,IF(T25="Información pública reservada",5,IF(T25="Información pública",1,)))) -> 0 | W25: =IF(V25="No clasificada",5,IF(V25="Baja",1,IF(V25="Media",3,IF(V25="Alta",5,)))) -> 0 | Y25: =IF(X25="No clasificada",5,IF(X25="Baja",1,IF(X25="Media",3,IF(X25="Alta",5,)))) -> 0 | Z25: =IF(OR(T25=0,V25=0,X25=0),"FALTAN DATOS",IF(AND(U25=1,W25=1,Y25=1),"BAJA",(IF(OR(AND(U25=5,W25=5),AND(U25=5,Y25=5),AND(U25=5,Y25=5),AND(U25=5,W25=5,Y25=5)),"ALTA","MEDIA")))) -> FALTAN DATOS | AD25: =IF(AC25="Sí","Ley 1581 de 2012",IF(AC25="No","Ley 1755 de 2015","")) | AE25: =IF(AC25="Sí","Artículo 10 y 13",IF(AC25="No","Artículo 27","")) | BC25: Planeación | CL25: Gestión Estadística | CM25: Calidad Educativa
U26: =IF(T26="No clasificada",5,IF(T26="Información pública clasificada",3,IF(T26="Información pública reservada",5,IF(T26="Información pública",1,)))) -> 0 | W26: =IF(V26="No clasificada",5,IF(V26="Baja",1,IF(V26="Media",3,IF(V26="Alta",5,)))) -> 0 | Y26: =IF(X26="No clasificada",5,IF(X26="Baja",1,IF(X26="Media",3,IF(X26="Alta",5,)))) -> 0 | Z26: =IF(OR(T26=0,V26=0,X26=0),"FALTAN DATOS",IF(AND(U26=1,W26=1,Y26=1),"BAJA",(IF(OR(AND(U26=5,W26=5),AND(U26=5,Y26=5),AND(U26=5,Y26=5),AND(U26=5,W26=5,Y26=5)),"ALTA","MEDIA")))) -> FALTAN DATOS | AD26: =IF(AC26="Sí","Ley 1581 de 2012",IF(AC26="No","Ley 1755 de 2015","")) | AE26: =IF(AC26="Sí","Artículo 10 y 13",IF(AC26="No","Artículo 27","")) | BC26: Salud | CL26: Control Interno | CM26: Cobertura Educativa
U27: =IF(T27="No clasificada",5,IF(T27="Información pública clasificada",3,IF(T27="Información pública reservada",5,IF(T27="Información pública",1,)))) -> 0 | W27: =IF(V27="No clasificada",5,IF(V27="Baja",1,IF(V27="Media",3,IF(V27="Alta",5,)))) -> 0 | Y27: =IF(X27="No clasificada",5,IF(X27="Baja",1,IF(X27="Media",3,IF(X27="Alta",5,)))) -> 0 | Z27: =IF(OR(T27=0,V27=0,X27=0),"FALTAN DATOS",IF(AND(U27=1,W27=1,Y27=1),"BAJA",(IF(OR(AND(U27=5,W27=5),AND(U27=5,Y27=5),AND(U27=5,Y27=5),AND(U27=5,W27=5,Y27=5)),"ALTA","MEDIA")))) -> FALTAN DATOS | AD27: =IF(AC27="Sí","Ley 1581 de 2012",IF(AC27="No","Ley 1755 de 2015","")) | AE27: =IF(AC27="Sí","Artículo 10 y 13",IF(AC27="No","Artículo 27","")) | BC27: Turismo | CM27: Inspección y Vigilancia Educativa
U28: =IF(T28="No clasificada",5,IF(T28="Información pública clasificada",3,IF(T28="Información pública reservada",5,IF(T28="Información pública",1,)))) -> 0 | W28: =IF(V28="No clasificada",5,IF(V28="Baja",1,IF(V28="Media",3,IF(V28="Alta",5,)))) -> 0 | Y28: =IF(X28="No clasificada",5,IF(X28="Baja",1,IF(X28="Media",3,IF(X28="Alta",5,)))) -> 0 | Z28: =IF(OR(T28=0,V28=0,X28=0),"FALTAN DATOS",IF(AND(U28=1,W28=1,Y28=1),"BAJA",(IF(OR(AND(U28=5,W28=5),AND(U28=5,Y28=5),AND(U28=5,Y28=5),AND(U28=5,W28=5,Y28=5)),"ALTA","MEDIA")))) -> FALTAN DATOS | AD28: =IF(AC28="Sí","Ley 1581 de 2012",IF(AC28="No","Ley 1755 de 2015","")) | AE28: =IF(AC28="Sí","Artículo 10 y 13",IF(AC28="No","Artículo 27","")) | BC28: Vivienda | CM28: Convivencia y Cultura Ciudadana (Inspección de policía - comisaría de familia, metrología)
U29: =IF(T29="No clasificada",5,IF(T29="Información pública clasificada",3,IF(T29="Información pública reservada",5,IF(T29="Información pública",1,)))) -> 0 | W29: =IF(V29="No clasificada",5,IF(V29="Baja",1,IF(V29="Media",3,IF(V29="Alta",5,)))) -> 0 | Y29: =IF(X29="No clasificada",5,IF(X29="Baja",1,IF(X29="Media",3,IF(X29="Alta",5,)))) -> 0 | Z29: =IF(OR(T29=0,V29=0,X29=0),"FALTAN DATOS",IF(AND(U29=1,W29=1,Y29=1),"BAJA",(IF(OR(AND(U29=5,W29=5),AND(U29=5,Y29=5),AND(U29=5,Y29=5),AND(U29=5,W29=5,Y29=5)),"ALTA","MEDIA")))) -> FALTAN DATOS | AD29: =IF(AC29="Sí","Ley 1581 de 2012",IF(AC29="No","Ley 1755 de 2015","")) | AE29: =IF(AC29="Sí","Artículo 10 y 13",IF(AC29="No","Artículo 27","")) | BC29: General | CM29: Gestión de Riesgo de Desastres
U30: =IF(T30="No clasificada",5,IF(T30="Información pública clasificada",3,IF(T30="Información pública reservada",5,IF(T30="Información pública",1,)))) -> 0 | W30: =IF(V30="No clasificada",5,IF(V30="Baja",1,IF(V30="Media",3,IF(V30="Alta",5,)))) -> 0 | Y30: =IF(X30="No clasificada",5,IF(X30="Baja",1,IF(X30="Media",3,IF(X30="Alta",5,)))) -> 0 | Z30: =IF(OR(T30=0,V30=0,X30=0),"FALTAN DATOS",IF(AND(U30=1,W30=1,Y30=1),"BAJA",(IF(OR(AND(U30=5,W30=5),AND(U30=5,Y30=5),AND(U30=5,Y30=5),AND(U30=5,W30=5,Y30=5)),"ALTA","MEDIA")))) -> FALTAN DATOS | AD30: =IF(AC30="Sí","Ley 1581 de 2012",IF(AC30="No","Ley 1755 de 2015","")) | AE30: =IF(AC30="Sí","Artículo 10 y 13",IF(AC30="No","Artículo 27","")) | BC30: Jurídica | CM30: Víctimas
U31: =IF(T31="No clasificada",5,IF(T31="Información pública clasificada",3,IF(T31="Información pública reservada",5,IF(T31="Información pública",1,)))) -> 0 | W31: =IF(V31="No clasificada",5,IF(V31="Baja",1,IF(V31="Media",3,IF(V31="Alta",5,)))) -> 0 | Y31: =IF(X31="No clasificada",5,IF(X31="Baja",1,IF(X31="Media",3,IF(X31="Alta",5,)))) -> 0 | Z31: =IF(OR(T31=0,V31=0,X31=0),"FALTAN DATOS",IF(AND(U31=1,W31=1,Y31=1),"BAJA",(IF(OR(AND(U31=5,W31=5),AND(U31=5,Y31=5),AND(U31=5,Y31=5),AND(U31=5,W31=5,Y31=5)),"ALTA","MEDIA")))) -> FALTAN DATOS | AD31: =IF(AC31="Sí","Ley 1581 de 2012",IF(AC31="No","Ley 1755 de 2015","")) | AE31: =IF(AC31="Sí","Artículo 10 y 13",IF(AC31="No","Artículo 27","")) | BC31: Seguridad y Convivencia | CM31: Gestión de Movilidad y Seguridad Vial
U32: =IF(T32="No clasificada",5,IF(T32="Información pública clasificada",3,IF(T32="Información pública reservada",5,IF(T32="Información pública",1,)))) -> 0 | W32: =IF(V32="No clasificada",5,IF(V32="Baja",1,IF(V32="Media",3,IF(V32="Alta",5,)))) -> 0 | Y32: =IF(X32="No clasificada",5,IF(X32="Baja",1,IF(X32="Media",3,IF(X32="Alta",5,)))) -> 0 | Z32: =IF(OR(T32=0,V32=0,X32=0),"FALTAN DATOS",IF(AND(U32=1,W32=1,Y32=1),"BAJA",(IF(OR(AND(U32=5,W32=5),AND(U32=5,Y32=5),AND(U32=5,Y32=5),AND(U32=5,W32=5,Y32=5)),"ALTA","MEDIA")))) -> FALTAN DATOS | AD32: =IF(AC32="Sí","Ley 1581 de 2012",IF(AC32="No","Ley 1755 de 2015","")) | AE32: =IF(AC32="Sí","Artículo 10 y 13",IF(AC32="No","Artículo 27","")) | BC32: Comunicaciones | CM32: Gestión de Vivienda y Saneamiento Básico
U33: =IF(T33="No clasificada",5,IF(T33="Información pública clasificada",3,IF(T33="Información pública reservada",5,IF(T33="Información pública",1,)))) -> 0 | W33: =IF(V33="No clasificada",5,IF(V33="Baja",1,IF(V33="Media",3,IF(V33="Alta",5,)))) -> 0 | Y33: =IF(X33="No clasificada",5,IF(X33="Baja",1,IF(X33="Media",3,IF(X33="Alta",5,)))) -> 0 | Z33: =IF(OR(T33=0,V33=0,X33=0),"FALTAN DATOS",IF(AND(U33=1,W33=1,Y33=1),"BAJA",(IF(OR(AND(U33=5,W33=5),AND(U33=5,Y33=5),AND(U33=5,Y33=5),AND(U33=5,W33=5,Y33=5)),"ALTA","MEDIA")))) -> FALTAN DATOS | AD33: =IF(AC33="Sí","Ley 1581 de 2012",IF(AC33="No","Ley 1755 de 2015","")) | AE33: =IF(AC33="Sí","Artículo 10 y 13",IF(AC33="No","Artículo 27","")) | BC33: Control I​nterno | CM33: Gestión Cultural
U34: =IF(T34="No clasificada",5,IF(T34="Información pública clasificada",3,IF(T34="Información pública reservada",5,IF(T34="Información pública",1,)))) -> 0 | W34: =IF(V34="No clasificada",5,IF(V34="Baja",1,IF(V34="Media",3,IF(V34="Alta",5,)))) -> 0 | Y34: =IF(X34="No clasificada",5,IF(X34="Baja",1,IF(X34="Media",3,IF(X34="Alta",5,)))) -> 0 | Z34: =IF(OR(T34=0,V34=0,X34=0),"FALTAN DATOS",IF(AND(U34=1,W34=1,Y34=1),"BAJA",(IF(OR(AND(U34=5,W34=5),AND(U34=5,Y34=5),AND(U34=5,Y34=5),AND(U34=5,W34=5,Y34=5)),"ALTA","MEDIA")))) -> FALTAN DATOS | AD34: =IF(AC34="Sí","Ley 1581 de 2012",IF(AC34="No","Ley 1755 de 2015","")) | AE34: =IF(AC34="Sí","Artículo 10 y 13",IF(AC34="No","Artículo 27","")) | BC34: Control Interno y Disciplinario​ | CM34: Gestión Turística
U35: =IF(T35="No clasificada",5,IF(T35="Información pública clasificada",3,IF(T35="Información pública reservada",5,IF(T35="Información pública",1,)))) -> 0 | W35: =IF(V35="No clasificada",5,IF(V35="Baja",1,IF(V35="Media",3,IF(V35="Alta",5,)))) -> 0 | Y35: =IF(X35="No clasificada",5,IF(X35="Baja",1,IF(X35="Media",3,IF(X35="Alta",5,)))) -> 0 | Z35: =IF(OR(T35=0,V35=0,X35=0),"FALTAN DATOS",IF(AND(U35=1,W35=1,Y35=1),"BAJA",(IF(OR(AND(U35=5,W35=5),AND(U35=5,Y35=5),AND(U35=5,Y35=5),AND(U35=5,W35=5,Y35=5)),"ALTA","MEDIA")))) -> FALTAN DATOS | AD35: =IF(AC35="Sí","Ley 1581 de 2012",IF(AC35="No","Ley 1755 de 2015","")) | AE35: =IF(AC35="Sí","Artículo 10 y 13",IF(AC35="No","Artículo 27","")) | BC35: Cooperación Internacion​al​ | CM35: Gestión para las Comunidades Étnicas
U36: =IF(T36="No clasificada",5,IF(T36="Información pública clasificada",3,IF(T36="Información pública reservada",5,IF(T36="Información pública",1,)))) -> 0 | W36: =IF(V36="No clasificada",5,IF(V36="Baja",1,IF(V36="Media",3,IF(V36="Alta",5,)))) -> 0 | Y36: =IF(X36="No clasificada",5,IF(X36="Baja",1,IF(X36="Media",3,IF(X36="Alta",5,)))) -> 0 | Z36: =IF(OR(T36=0,V36=0,X36=0),"FALTAN DATOS",IF(AND(U36=1,W36=1,Y36=1),"BAJA",(IF(OR(AND(U36=5,W36=5),AND(U36=5,Y36=5),AND(U36=5,Y36=5),AND(U36=5,W36=5,Y36=5)),"ALTA","MEDIA")))) -> FALTAN DATOS | AD36: =IF(AC36="Sí","Ley 1581 de 2012",IF(AC36="No","Ley 1755 de 2015","")) | AE36: =IF(AC36="Sí","Artículo 10 y 13",IF(AC36="No","Artículo 27","")) | BC36: Tecnologías de la Información y las Comunicaciones​ | CM36: Mantenimiento Espacios de Uso Público e Infraestructura Vial
U37: =IF(T37="No clasificada",5,IF(T37="Información pública clasificada",3,IF(T37="Información pública reservada",5,IF(T37="Información pública",1,)))) -> 0 | W37: =IF(V37="No clasificada",5,IF(V37="Baja",1,IF(V37="Media",3,IF(V37="Alta",5,)))) -> 0 | Y37: =IF(X37="No clasificada",5,IF(X37="Baja",1,IF(X37="Media",3,IF(X37="Alta",5,)))) -> 0 | Z37: =IF(OR(T37=0,V37=0,X37=0),"FALTAN DATOS",IF(AND(U37=1,W37=1,Y37=1),"BAJA",(IF(OR(AND(U37=5,W37=5),AND(U37=5,Y37=5),AND(U37=5,Y37=5),AND(U37=5,W37=5,Y37=5)),"ALTA","MEDIA")))) -> FALTAN DATOS | AD37: =IF(AC37="Sí","Ley 1581 de 2012",IF(AC37="No","Ley 1755 de 2015","")) | AE37: =IF(AC37="Sí","Artículo 10 y 13",IF(AC37="No","Artículo 27","")) | BC37: Progr​amas Especiales​ | CM37: Sostenibilidad Ambiental y Minera
U38: =IF(T38="No clasificada",5,IF(T38="Información pública clasificada",3,IF(T38="Información pública reservada",5,IF(T38="Información pública",1,)))) -> 0 | W38: =IF(V38="No clasificada",5,IF(V38="Baja",1,IF(V38="Media",3,IF(V38="Alta",5,)))) -> 0 | Y38: =IF(X38="No clasificada",5,IF(X38="Baja",1,IF(X38="Media",3,IF(X38="Alta",5,)))) -> 0 | Z38: =IF(OR(T38=0,V38=0,X38=0),"FALTAN DATOS",IF(AND(U38=1,W38=1,Y38=1),"BAJA",(IF(OR(AND(U38=5,W38=5),AND(U38=5,Y38=5),AND(U38=5,Y38=5),AND(U38=5,W38=5,Y38=5)),"ALTA","MEDIA")))) -> FALTAN DATOS | AD38: =IF(AC38="Sí","Ley 1581 de 2012",IF(AC38="No","Ley 1755 de 2015","")) | AE38: =IF(AC38="Sí","Artículo 10 y 13",IF(AC38="No","Artículo 27","")) | BC38: Posconflicto​ | CM38: Atención Social y Participación Ciudadana
... U42: =IF(T42="No clasificada",5,IF(T42="Información pública clasificada",3,IF(T42="Información pública reservada",5,IF(T42="Información pública",1,)))) -> 0 | W42: =IF(V42="No clasificada",5,IF(V42="Baja",1,IF(V42="Media",3,IF(V42="Alta",5,)))) -> 0 | Y42: =IF(X42="No clasificada",5,IF(X42="Baja",1,IF(X42="Media",3,IF(X42="Alta",5,)))) -> 0 | Z42: =IF(OR(T42=0,V42=0,X42=0),"FALTAN DATOS",IF(AND(U42=1,W42=1,Y42=1),"BAJA",(IF(OR(AND(U42=5,W42=5),AND(U42=5,Y42=5),AND(U42=5,Y42=5),AND(U42=5,W42=5,Y42=5)),"ALTA","MEDIA")))) -> FALTAN DATOS | AD42: =IF(AC42="Sí","Ley 1581 de 2012",IF(AC42="No","Ley 1755 de 2015","")) | AE42: =IF(AC42="Sí","Artículo 10 y 13",IF(AC42="No","Artículo 27","")) | BC42: Gestión Catastral | CM42: Fiscalización
U43: =IF(T43="No clasificada",5,IF(T43="Información pública clasificada",3,IF(T43="Información pública reservada",5,IF(T43="Información pública",1,)))) -> 0 | W43: =IF(V43="No clasificada",5,IF(V43="Baja",1,IF(V43="Media",3,IF(V43="Alta",5,)))) -> 0 | Y43: =IF(X43="No clasificada",5,IF(X43="Baja",1,IF(X43="Media",3,IF(X43="Alta",5,)))) -> 0 | Z43: =IF(OR(T43=0,V43=0,X43=0),"FALTAN DATOS",IF(AND(U43=1,W43=1,Y43=1),"BAJA",(IF(OR(AND(U43=5,W43=5),AND(U43=5,Y43=5),AND(U43=5,Y43=5),AND(U43=5,W43=5,Y43=5)),"ALTA","MEDIA")))) -> FALTAN DATOS | AD43: =IF(AC43="Sí","Ley 1581 de 2012",IF(AC43="No","Ley 1755 de 2015","")) | AE43: =IF(AC43="Sí","Artículo 10 y 13",IF(AC43="No","Artículo 27","")) | CM43: Contabilidad General
U44: =IF(T44="No clasificada",5,IF(T44="Información pública clasificada",3,IF(T44="Información pública reservada",5,IF(T44="Información pública",1,)))) -> 0 | W44: =IF(V44="No clasificada",5,IF(V44="Baja",1,IF(V44="Media",3,IF(V44="Alta",5,)))) -> 0 | Y44: =IF(X44="No clasificada",5,IF(X44="Baja",1,IF(X44="Media",3,IF(X44="Alta",5,)))) -> 0 | Z44: =IF(OR(T44=0,V44=0,X44=0),"FALTAN DATOS",IF(AND(U44=1,W44=1,Y44=1),"BAJA",(IF(OR(AND(U44=5,W44=5),AND(U44=5,Y44=5),AND(U44=5,Y44=5),AND(U44=5,W44=5,Y44=5)),"ALTA","MEDIA")))) -> FALTAN DATOS | AD44: =IF(AC44="Sí","Ley 1581 de 2012",IF(AC44="No","Ley 1755 de 2015","")) | AE44: =IF(AC44="Sí","Artículo 10 y 13",IF(AC44="No","Artículo 27","")) | CM44: Gestión Presupuestal
U45: =IF(T45="No clasificada",5,IF(T45="Información pública clasificada",3,IF(T45="Información pública reservada",5,IF(T45="Información pública",1,)))) -> 0 | W45: =IF(V45="No clasificada",5,IF(V45="Baja",1,IF(V45="Media",3,IF(V45="Alta",5,)))) -> 0 | Y45: =IF(X45="No clasificada",5,IF(X45="Baja",1,IF(X45="Media",3,IF(X45="Alta",5,)))) -> 0 | Z45: =IF(OR(T45=0,V45=0,X45=0),"FALTAN DATOS",IF(AND(U45=1,W45=1,Y45=1),"BAJA",(IF(OR(AND(U45=5,W45=5),AND(U45=5,Y45=5),AND(U45=5,Y45=5),AND(U45=5,W45=5,Y45=5)),"ALTA","MEDIA")))) -> FALTAN DATOS | AD45: =IF(AC45="Sí","Ley 1581 de 2012",IF(AC45="No","Ley 1755 de 2015","")) | AE45: =IF(AC45="Sí","Artículo 10 y 13",IF(AC45="No","Artículo 27","")) | CM45: Actualización Catastral
U46: =IF(T46="No clasificada",5,IF(T46="Información pública clasificada",3,IF(T46="Información pública reservada",5,IF(T46="Información pública",1,)))) -> 0 | W46: =IF(V46="No clasificada",5,IF(V46="Baja",1,IF(V46="Media",3,IF(V46="Alta",5,)))) -> 0 | Y46: =IF(X46="No clasificada",5,IF(X46="Baja",1,IF(X46="Media",3,IF(X46="Alta",5,)))) -> 0 | Z46: =IF(OR(T46=0,V46=0,X46=0),"FALTAN DATOS",IF(AND(U46=1,W46=1,Y46=1),"BAJA",(IF(OR(AND(U46=5,W46=5),AND(U46=5,Y46=5),AND(U46=5,Y46=5),AND(U46=5,W46=5,Y46=5)),"ALTA","MEDIA")))) -> FALTAN DATOS | AD46: =IF(AC46="Sí","Ley 1581 de 2012",IF(AC46="No","Ley 1755 de 2015","")) | AE46: =IF(AC46="Sí","Artículo 10 y 13",IF(AC46="No","Artículo 27","")) | CM46: Conservación Catastral
U47: =IF(T47="No clasificada",5,IF(T47="Información pública clasificada",3,IF(T47="Información pública reservada",5,IF(T47="Información pública",1,)))) -> 0 | W47: =IF(V47="No clasificada",5,IF(V47="Baja",1,IF(V47="Media",3,IF(V47="Alta",5,)))) -> 0 | Y47: =IF(X47="No clasificada",5,IF(X47="Baja",1,IF(X47="Media",3,IF(X47="Alta",5,)))) -> 0 | Z47: =IF(OR(T47=0,V47=0,X47=0),"FALTAN DATOS",IF(AND(U47=1,W47=1,Y47=1),"BAJA",(IF(OR(AND(U47=5,W47=5),AND(U47=5,Y47=5),AND(U47=5,Y47=5),AND(U47=5,W47=5,Y47=5)),"ALTA","MEDIA")))) -> FALTAN DATOS | AD47: =IF(AC47="Sí","Ley 1581 de 2012",IF(AC47="No","Ley 1755 de 2015","")) | AE47: =IF(AC47="Sí","Artículo 10 y 13",IF(AC47="No","Artículo 27","")) | CM47: Atención al Ciudadano
U48: =IF(T48="No clasificada",5,IF(T48="Información pública clasificada",3,IF(T48="Información pública reservada",5,IF(T48="Información pública",1,)))) -> 0 | W48: =IF(V48="No clasificada",5,IF(V48="Baja",1,IF(V48="Media",3,IF(V48="Alta",5,)))) -> 0 | Y48: =IF(X48="No clasificada",5,IF(X48="Baja",1,IF(X48="Media",3,IF(X48="Alta",5,)))) -> 0 | Z48: =IF(OR(T48=0,V48=0,X48=0),"FALTAN DATOS",IF(AND(U48=1,W48=1,Y48=1),"BAJA",(IF(OR(AND(U48=5,W48=5),AND(U48=5,Y48=5),AND(U48=5,Y48=5),AND(U48=5,W48=5,Y48=5)),"ALTA","MEDIA")))) -> FALTAN DATOS | AD48: =IF(AC48="Sí","Ley 1581 de 2012",IF(AC48="No","Ley 1755 de 2015","")) | AE48: =IF(AC48="Sí","Artículo 10 y 13",IF(AC48="No","Artículo 27","")) | CM48: Gestión Documental (Archivo - Ventanilla Única)
U49: =IF(T49="No clasificada",5,IF(T49="Información pública clasificada",3,IF(T49="Información pública reservada",5,IF(T49="Información pública",1,)))) -> 0 | W49: =IF(V49="No clasificada",5,IF(V49="Baja",1,IF(V49="Media",3,IF(V49="Alta",5,)))) -> 0 | Y49: =IF(X49="No clasificada",5,IF(X49="Baja",1,IF(X49="Media",3,IF(X49="Alta",5,)))) -> 0 | Z49: =IF(OR(T49=0,V49=0,X49=0),"FALTAN DATOS",IF(AND(U49=1,W49=1,Y49=1),"BAJA",(IF(OR(AND(U49=5,W49=5),AND(U49=5,Y49=5),AND(U49=5,Y49=5),AND(U49=5,W49=5,Y49=5)),"ALTA","MEDIA")))) -> FALTAN DATOS | AD49: =IF(AC49="Sí","Ley 1581 de 2012",IF(AC49="No","Ley 1755 de 2015","")) | AE49: =IF(AC49="Sí","Artículo 10 y 13",IF(AC49="No","Artículo 27","")) | CM49: Administración Plaza de Mercado
U50: =IF(T50="No clasificada",5,IF(T50="Información pública clasificada",3,IF(T50="Información pública reservada",5,IF(T50="Información pública",1,)))) -> 0 | W50: =IF(V50="No clasificada",5,IF(V50="Baja",1,IF(V50="Media",3,IF(V50="Alta",5,)))) -> 0 | Y50: =IF(X50="No clasificada",5,IF(X50="Baja",1,IF(X50="Media",3,IF(X50="Alta",5,)))) -> 0 | Z50: =IF(OR(T50=0,V50=0,X50=0),"FALTAN DATOS",IF(AND(U50=1,W50=1,Y50=1),"BAJA",(IF(OR(AND(U50=5,W50=5),AND(U50=5,Y50=5),AND(U50=5,Y50=5),AND(U50=5,W50=5,Y50=5)),"ALTA","MEDIA")))) -> FALTAN DATOS | AD50: =IF(AC50="Sí","Ley 1581 de 2012",IF(AC50="No","Ley 1755 de 2015","")) | AE50: =IF(AC50="Sí","Artículo 10 y 13",IF(AC50="No","Artículo 27","")) | CM50: Gestión de Inventarios de Bienes Muebles e Inmuebles
U51: =IF(T51="No clasificada",5,IF(T51="Información pública clasificada",3,IF(T51="Información pública reservada",5,IF(T51="Información pública",1,)))) -> 0 | W51: =IF(V51="No clasificada",5,IF(V51="Baja",1,IF(V51="Media",3,IF(V51="Alta",5,)))) -> 0 | Y51: =IF(X51="No clasificada",5,IF(X51="Baja",1,IF(X51="Media",3,IF(X51="Alta",5,)))) -> 0 | Z51: =IF(OR(T51=0,V51=0,X51=0),"FALTAN DATOS",IF(AND(U51=1,W51=1,Y51=1),"BAJA",(IF(OR(AND(U51=5,W51=5),AND(U51=5,Y51=5),AND(U51=5,Y51=5),AND(U51=5,W51=5,Y51=5)),"ALTA","MEDIA")))) -> FALTAN DATOS | AD51: =IF(AC51="Sí","Ley 1581 de 2012",IF(AC51="No","Ley 1755 de 2015","")) | AE51: =IF(AC51="Sí","Artículo 10 y 13",IF(AC51="No","Artículo 27","")) | CM51: Administración del Talento Humano
...

Sheet  1 INSTRUCTIVO
B2: Matriz Mapa de Riesgos | J2: INSTRUCTIVO DILIGENCIAMIENTO DE ACTIVOS DE INFORMACIÓN
J3: OBJETIVO Establecer de manera clara, detallada y paso a paso la forma correcta de diligenciar cada campo del Formato de Gestión y Clasificación de Activos de Información, permitiendo a las dependencias de la entidad identificar, clasificar, valorar y proteger sus activos de información conforme a los lineamientos del Modelo de Seguridad y Privacidad de la Información (MSPI), ISO 27001, Ley 1712 de 2014, Ley 1581 de 2012 y demás normatividad aplicable. A continuación se presenta el diligenciamiento fila por fila para facilitar el registro del formato.
B4: Con la expedición del Decreto 1499 de 2017 “Por medio del cual se modifica el Decreto 1083 de 2015, Decreto Único Reglamentario del Sector Función Pública, en lo relacionado con el Sistema de Gestión establecido en el artículo 133 de la Ley 1753 de 2015”, se crea un solo Sistema de Gestión y se alinea con el Sistema de Control Interno, hoy todas las entidades públicas requieren actualizar y/o implementar el Modelo Integrado de Planeación y Gestión MIPG, modelo que incorpora el Modelo Estándar de Control Interno MECI a través de la 7a dimensión del mismo. En este marco general, el proceso de administración del riesgo es un esfuerzo conjunto entre la Alta Dirección y los servidores en todos sus niveles, ejercicio que inicia con la formulación de la política de Administración del Riesgo, la cual incluye los niveles de responsabilidad frente al seguimiento y evaluación, aspectos que deberán definirse acorde con el Esquema de Líneas de Defensa vinculado a la Dimensión 7. Teniendo en cuenta lo anterior y dada la necesidad de las entidades frente a la estructuración de los mapas de riesgos, como herramienta fundamental frente a la gestión del riesgo, el presente formato desarrolla un esquema completo acorde con los contenidos metodológicos de la Guía para la Administración del Riesgo y el diseño de controles V5. El formato cuenta con celdas parametrizadas y permite contar con los respectivos mapas de calor para riesgo inherente y riesgo residual. | J4: FASE | K4: Columna | L4: Descripción - Lineamientos para el diligenciamiento
J5: FASE 1 | K5: MACROPROCESO | L5: Seleccione el macroproceso de la lista desplegable entre: Direccionamiento Estratégico Gestión de la Información y las Comunicaciones Gestión de Servicios de Salud Gestión Educativa Convivencia Ciudadana, Seguridad y Orden Público Desarrollo Social Integral y Ambiental del Territorio Gestión Financiera Gestión Catastral Gestión Administrativa Gestión del Talento Humano Gestión Jurídica Gestión Estadística Control Interno
B6: Orientaciones Generales | K6: PROCESO | L6: Seleccione el proceso relacionado con el macroproceso y con el activo de información de la lista desplegable.
B7: Antes de iniciar con el diligenciamiento de la información en la matriz, se requiere haber avanzado en el análisis del proceso, su objetivo, alcance, actividades clave, considere los lineamientos establecidos en el Paso 2: identificación del riesgo, donde se explica ampliamente las bases para adelantar este análisis. Así mismo, considere en el Paso 3: valoración del riesgo los lineamientos para definir el No. de veces que se hace la actividad con la cual se relaciona el riesgo y su impacto en términos económicos o reputacionales. En este mismo paso se analizan los controles que deben responder a los atributos de eficiencia e informativos. | K7: CÓDIGO DEL SISTEMA DE GESTIÓN DOCUMENTAL | L7: Diligencie el código documental asignado en la Tabla de Retención Documental (TDR) o instrumentos archivísticos. Si no existe, escriba “No aplica”.
K8: IDENTIFICADOR | L8: Registre un código único que permita identificar el activo. Se recomienda usar una combinación de la dependencia + número consecutivo. Por ejemplo, TIC-001
B9: Las hojas se encuentran protegidas para evidar dañar las formulas, para desprotegerlas no se requiere contraseña | K9: TIPO | L9: Seleccione el tipo de activo de información de la lista desplegable entre: Información (Bases de datos de clientes, contratos, hojas de cálculo financieras, manuales internos, correos electrónicos, reportes de ventas) Software (Sistema ERP, antivirus, sistema operativo Windows/Linux, aplicación contable, CRM, aplicaciones móviles) Hardware (Servidores, computadores portátiles, impresoras, discos duros externos, routers, cámaras de seguridad) Servicios (Servicio de correo electrónico corporativo, hosting web, nube (AWS/Azure), internet empresarial, mesa de ayuda TI) Intangibles (Marca de la empresa, propiedad intelectual, licencias, patentes, reputación corporativa, know-how) Componentes de red (Switches, firewalls, access points Wi-Fi, cables de red, módems, balanceadores de carga) Recurso humano No aplica
K10: OFICINA | L10: Seleccione la dependencia u oficina responsable o relacionada con el activo de información de la lista desplegable entre: Despacho del Alcalde Agricultura Ambiente Asuntos Étnicos Cultura Desarrollo Social Educación Gobierno Gestión Institucional Hacienda Infraestructura Planeación Salud Turismo Vivienda General Jurídica Seguridad y Convivencia Comunicaciones Control I​nterno Control Interno y Disciplinario​ Cooperación Internacion​al​ Tecnologías de la Información y las Comunicaciones​ Progr​amas Especiales​ Posconflicto​ Equidad de Género​ Juventudes Libertad Religiosa Gestión Catastral
B11: Se debe ingresar información solo en las celdas identificadas con color NARANJA CLARO, las demás contienen formulas de autollenado | K11: SERIE DOCUMENTAL | L11: Ingrese la serie documental del área, dependencia o proceso donde se encuentra identificado el activo. Por ejemplo: Si el activo se encuentra en la secretaría jurírica y el activo es un PROCESO JURIDICO el número de serie 34-42
K12: SUBSERIE DOCUMENTAL | L12: Ingrese la subserie documental correspondiente a la serie donde se encuentra el activo. Por ejemplo: Para el PROCESO JURIDICO si es un proceso de cobro coactivo el número de serie sería 34-42 01
B13: El formato de fecha es: DD/MM/AAAA | K13: NOMBRE | L13: Registre el nombre del activo de información de forma clara y específica.
K14: DESCRIPCIÓN | L14: Describa de manera resumida la función, contenido o propósito del activo.
B15: El archivo contiene las siguientes hojas: | K15: NOMBRE DEL RESPONSABLE DE LA PRODUCCIÓN DE LA INFORMACIÓN (PROPIETARIO DEL ACTIVO) | L15: Diligencie el nombre completo de la persona encargada de crear, generar o administrar funcionalmente la información.
K16: FECHA DE GENERACIÓN DE LA INFORMACIÓN | L16: Ingrese la fecha en la que el activo de información fue creado o comenzó a generarse.
B17: 1 INSTRUCTIVO: Identifica el contenido del archivo y su funcionalidad | K17: NOMBRE DEL RESPONSABLE DE LA INFORMACIÓN (CUSTODIO DEL ACTIVO) | L17: Ingrese el nombre completo de la persona encargada de custodiar, almacenar o mantener el activo.
K18: FECHA DE INGRESO DEL ACTIVO AL ARCHIVO | L18: Ingrese la fecha en la que el activo fue archivado o incorporado al sistema de gestión documental, formato (DD/MM/AAAA)
B19: 2 CONTEXTO E IDENTIFICACIÓN: Se establece el Número, Descripción y Factor del riesgo | K19: MEDIO DE CONSERVACIÓN | L19: Seleccione el medio de conservación del activo (físico, formato, contenedor o soporte tecnológico) de la lista desplegable entre: Fisico Digital No aplica
K20: FORMATO | L20: Seleccione el tipo de formato en el que se presenta o consulta el activo de la lista desplegable entre: Formato Audio Documento de texto Documento PDF Presentación Hoja de calculo Imagen Video Base de datos Otro No aplica
C21: Columna | E21: Descripción - Lineamientos para el diligenciamiento | K21: IDIOMA | L21: Establezca el idioma en el que está redactado o disponible el activo.
C22: Proceso | E22: Diligencie el nombre del proceso al cual se le identificarán y valorarán los riesgos.
C23: Objetivo del Proceso | E23: Diligencie el objetivo del proceso. | J23: FASE 2 | K23: CONFIDENCIALIDAD | L23: Seleccione el nivel de restricción del activo de información según el acceso permitido de la lista desplegable entre: Información pública reservada: Es la información que no debe ser divulgada debido a que esto puede causar daño a intereses públicos. Solamente la Constitución o la ley pueden definir qué información es de carácter reservado. Información pública clasificada: Es la información que no debe ser divulgada debido a que se pueden vulnerar los derechos de las personas naturales o jurídicas, tales como: derecho de las personas a la intimidad, derecho a la vida, salud o seguridad y los secretos comerciales, industriales y profesionales. Información pública: Información que puede ser entregada o publicada sin restricciones a cualquier persona dentro y fuera de la entidad, sin que esto implique daños a terceros ni a las actividades y procesos de la entidad. No clasificada: Activos de Información que deben ser incluidos en el inventario y que aún no han sido clasificados, deben ser tratados como activos de INFORMACIÓN PÚBLICA RESERVADA. como: Hardware, Colaboradores de Planta o Contratistas
